[2019-12-22 18:20:21,727]{/home/alta14/Desktop/AltA/W5pro/prowrap/lib/python3.6/site-packages/flask/app.py:1891} ERROR - Exception on /internal [POST]
Traceback (most recent call last):
  File "/home/alta14/Desktop/AltA/W5pro/prowrap/lib/python3.6/site-packages/flask/app.py", line 1949, in full_dispatch_request
    rv = self.dispatch_request()
  File "/home/alta14/Desktop/AltA/W5pro/prowrap/lib/python3.6/site-packages/flask/app.py", line 1935, in dispatch_request
    return self.view_functions[rule.endpoint](**req.view_args)
  File "/home/alta14/Desktop/AltA/W5pro/prowrap/lib/python3.6/site-packages/flask_restful/__init__.py", line 458, in wrapper
    resp = resource(*args, **kwargs)
  File "/home/alta14/Desktop/AltA/W5pro/prowrap/lib/python3.6/site-packages/flask/views.py", line 89, in view
    return self.dispatch_request(*args, **kwargs)
  File "/home/alta14/Desktop/AltA/W5pro/prowrap/lib/python3.6/site-packages/flask_restful/__init__.py", line 573, in dispatch_request
    resp = meth(*args, **kwargs)
  File "/home/alta14/Desktop/AltA/W5pro/prowrap/lib/python3.6/site-packages/flask_jwt_extended/view_decorators.py", line 107, in wrapper
    verify_jwt_in_request()
  File "/home/alta14/Desktop/AltA/W5pro/prowrap/lib/python3.6/site-packages/flask_jwt_extended/view_decorators.py", line 32, in verify_jwt_in_request
    jwt_data, jwt_header = _decode_jwt_from_request(request_type='access')
  File "/home/alta14/Desktop/AltA/W5pro/prowrap/lib/python3.6/site-packages/flask_jwt_extended/view_decorators.py", line 314, in _decode_jwt_from_request
    raise NoAuthorizationError(errors[0])
flask_jwt_extended.exceptions.NoAuthorizationError: Missing Authorization Header
[2019-12-22 18:20:21,736]{/home/alta14/Desktop/AltA/W5pro/collabflaskproject/quotify/blueprints/__init__.py:77} ERROR - REQUEST_LOG	{"status_code": 500, "request": null, "response": {"message": "Internal Server Error"}}
[2019-12-22 18:20:42,922]{/home/alta14/Desktop/AltA/W5pro/collabflaskproject/quotify/blueprints/__init__.py:73} INFO - REQUEST_LOG	{"status_code": 200, "request": null, "response": {"id": 1, "username": "fadhil", "password": "43ef7c7a4e981c79cbf9520d7437bdc7", "created_at": "2019-12-22 18:20:42", "updated_at": null}}
[2019-12-22 18:22:41,312]{/home/alta14/Desktop/AltA/W5pro/collabflaskproject/quotify/blueprints/__init__.py:73} INFO - REQUEST_LOG	{"status_code": 200, "request": null, "response": {"id": 2, "username": "fadhil2", "password": "ffbc4cb3c7d0904d053a3f9d28a8a9c9", "created_at": "2019-12-22 18:22:41", "updated_at": null}}
[2019-12-22 18:27:31,395]{/home/alta14/Desktop/AltA/W5pro/collabflaskproject/quotify/blueprints/__init__.py:73} INFO - REQUEST_LOG	{"status_code": 200, "request": null, "response": {"token": "eyJ0eXAiOiJKV1QiLCJhbGciOiJIUzI1NiJ9.eyJpYXQiOjE1NzcwMTQwNTEsIm5iZiI6MTU3NzAxNDA1MSwianRpIjoiMTQ5NWE4NmYtY2NkMi00YmYwLTgxMzMtMzM3NDg5OGI2ZThhIiwiZXhwIjoxNTc3MTAwNDUxLCJpZGVudGl0eSI6ImZhZGhpbDIiLCJmcmVzaCI6ZmFsc2UsInR5cGUiOiJhY2Nlc3MiLCJ1c2VyX2NsYWltcyI6eyJpZCI6MiwidXNlcm5hbWUiOiJmYWRoaWwyIiwiaXNhZG1pbiI6ZmFsc2V9fQ.wMKCgrzzofMgdS0kla9oehPEfCMw2fu3LmpYD8Zx_nQ"}}
[2019-12-22 18:30:43,697]{/home/alta14/Desktop/AltA/W5pro/prowrap/lib/python3.6/site-packages/flask/app.py:1891} ERROR - Exception on /gambar [POST]
Traceback (most recent call last):
  File "/home/alta14/Desktop/AltA/W5pro/collabflaskproject/quotify/blueprints/gambar/resources.py", line 87, in post
    urlBimon = main(args['arg3'],args['arg4'],urlAwal)['img_url']
KeyError: 'img_url'

During handling of the above exception, another exception occurred:

Traceback (most recent call last):
  File "/home/alta14/Desktop/AltA/W5pro/prowrap/lib/python3.6/site-packages/flask/app.py", line 1949, in full_dispatch_request
    rv = self.dispatch_request()
  File "/home/alta14/Desktop/AltA/W5pro/prowrap/lib/python3.6/site-packages/flask/app.py", line 1935, in dispatch_request
    return self.view_functions[rule.endpoint](**req.view_args)
  File "/home/alta14/Desktop/AltA/W5pro/prowrap/lib/python3.6/site-packages/flask_restful/__init__.py", line 458, in wrapper
    resp = resource(*args, **kwargs)
  File "/home/alta14/Desktop/AltA/W5pro/prowrap/lib/python3.6/site-packages/flask/views.py", line 89, in view
    return self.dispatch_request(*args, **kwargs)
  File "/home/alta14/Desktop/AltA/W5pro/prowrap/lib/python3.6/site-packages/flask_restful/__init__.py", line 573, in dispatch_request
    resp = meth(*args, **kwargs)
  File "/home/alta14/Desktop/AltA/W5pro/prowrap/lib/python3.6/site-packages/flask_jwt_extended/view_decorators.py", line 108, in wrapper
    return fn(*args, **kwargs)
  File "/home/alta14/Desktop/AltA/W5pro/collabflaskproject/quotify/blueprints/gambar/resources.py", line 91, in post
    MergeResource.merge(urlAwal,a,b)
  File "/home/alta14/Desktop/AltA/W5pro/collabflaskproject/quotify/blueprints/gambar/scriptWoka.py", line 168, in merge
    uploads('mantap.jpg')
NameError: name 'uploads' is not defined
[2019-12-22 18:30:43,702]{/home/alta14/Desktop/AltA/W5pro/collabflaskproject/quotify/blueprints/__init__.py:77} ERROR - REQUEST_LOG	{"status_code": 500, "request": null, "response": {"message": "Internal Server Error"}}
[2019-12-22 18:37:02,402]{/home/alta14/Desktop/AltA/W5pro/prowrap/lib/python3.6/site-packages/flask/app.py:1891} ERROR - Exception on /gambar [POST]
Traceback (most recent call last):
  File "/home/alta14/Desktop/AltA/W5pro/collabflaskproject/quotify/blueprints/gambar/resources.py", line 87, in post
    urlBimon = main(args['arg3'],args['arg4'],urlAwal)['img_url']
KeyError: 'img_url'

During handling of the above exception, another exception occurred:

Traceback (most recent call last):
  File "/home/alta14/Desktop/AltA/W5pro/prowrap/lib/python3.6/site-packages/flask/app.py", line 1949, in full_dispatch_request
    rv = self.dispatch_request()
  File "/home/alta14/Desktop/AltA/W5pro/prowrap/lib/python3.6/site-packages/flask/app.py", line 1935, in dispatch_request
    return self.view_functions[rule.endpoint](**req.view_args)
  File "/home/alta14/Desktop/AltA/W5pro/prowrap/lib/python3.6/site-packages/flask_restful/__init__.py", line 458, in wrapper
    resp = resource(*args, **kwargs)
  File "/home/alta14/Desktop/AltA/W5pro/prowrap/lib/python3.6/site-packages/flask/views.py", line 89, in view
    return self.dispatch_request(*args, **kwargs)
  File "/home/alta14/Desktop/AltA/W5pro/prowrap/lib/python3.6/site-packages/flask_restful/__init__.py", line 573, in dispatch_request
    resp = meth(*args, **kwargs)
  File "/home/alta14/Desktop/AltA/W5pro/prowrap/lib/python3.6/site-packages/flask_jwt_extended/view_decorators.py", line 108, in wrapper
    return fn(*args, **kwargs)
  File "/home/alta14/Desktop/AltA/W5pro/collabflaskproject/quotify/blueprints/gambar/resources.py", line 91, in post
    terakhir = MergeResource.merge(urlAwal,a,b)
  File "/home/alta14/Desktop/AltA/W5pro/collabflaskproject/quotify/blueprints/gambar/scriptWoka.py", line 168, in merge
    url_out = self.uploads('mantap.jpg')
NameError: name 'self' is not defined
[2019-12-22 18:37:02,409]{/home/alta14/Desktop/AltA/W5pro/collabflaskproject/quotify/blueprints/__init__.py:77} ERROR - REQUEST_LOG	{"status_code": 500, "request": null, "response": {"message": "Internal Server Error"}}
[2019-12-22 19:26:46,141]{/home/alta14/Desktop/AltA/W5pro/collabflaskproject/quotify/blueprints/__init__.py:84} INFO - REQUEST_LOG	{"status_code": 200, "request": null, "response": {"status": "success", "url_to_see": "https://img37.pixhost.to/images/250/130726214_mantap.jpg"}}
